<?xml version="1.0" ?>
<robot name="polaris_ranger_xp900">
  <joint name="front_left_steering_joint" type="revolute">
    <parent link="chassis"/>
    <child link="front_left_wheel_steering_block"/>
    <origin rpy="1.57079  0       0" xyz="1.20222  0.5      0.35515"/>
    <axis xyz="0  1  0"/>
    <limit effort="0.0" lower="-0.7727" upper="0.7727" velocity="0.0"/>
  </joint>
  <joint name="front_left_wheel_joint" type="fixed">
    <parent link="front_left_wheel_steering_block"/>
    <child link="front_left_wheel"/>
    <origin rpy="-3.09079  0       0" xyz="0      -0.00818 -0.21562"/>
    <axis xyz="0.00000000e+00   8.30000000e-04   1.00000000e+00"/>
    <limit effort="0" lower="0" upper="0" velocity="0"/>
  </joint>
  <joint name="front_right_steering_joint" type="revolute">
    <parent link="chassis"/>
    <child link="front_right_wheel_steering_block"/>
    <origin rpy="1.57079  0       0" xyz="1.20222 -0.5      0.35515"/>
    <axis xyz="0  1  0"/>
    <limit effort="0.0" lower="-0.7727" upper="0.7727" velocity="0.0"/>
  </joint>
  <joint name="front_right_wheel_joint" type="fixed">
    <parent link="front_right_wheel_steering_block"/>
    <child link="front_right_wheel"/>
    <origin rpy="-0.05079  0       0" xyz="0      -0.00818  0.21562"/>
    <axis xyz="0.00000000e+00   8.30000000e-04  -1.00000000e+00"/>
    <limit effort="0" lower="0" upper="0" velocity="0"/>
  </joint>
  <joint name="rear_left_wheel_joint" type="fixed">
    <parent link="chassis"/>
    <child link="rear_left_wheel"/>
    <origin rpy="-1.52  0    0" xyz="-0.99377  0.71562  0.34697"/>
    <axis xyz="0.00000000e+00   8.30000000e-04   1.00000000e+00"/>
    <limit effort="0" lower="0" upper="0" velocity="0"/>
  </joint>
  <joint name="rear_right_wheel_joint" type="fixed">
    <parent link="chassis"/>
    <child link="rear_right_wheel"/>
    <origin rpy="1.52  0    0" xyz="-0.99377 -0.61574  0.34189"/>
    <axis xyz="0.00000000e+00   8.30000000e-04  -1.00000000e+00"/>
    <limit effort="0" lower="0" upper="0" velocity="0"/>
  </joint>
  <!--<joint name="rear_differential_joint" type="fixed">
    <parent link="rear_left_wheel"/>
    <child link="rear_right_wheel"/>
    <origin rpy="3.04  0    0" xyz="0      -0.07267 -1.42939"/>
    <axis xyz="0       0.05077 -0.99871"/>
    <limit effort="0" lower="0" upper="0" velocity="0"/>
  </joint>-->
  <joint name="gas_joint" type="prismatic">
    <parent link="chassis"/>
    <child link="gas_pedal"/>
    <origin rpy="0  0  0" xyz="0.63     0.1      0.57999"/>
    <axis xyz="0.7071  0     -0.7071"/>
    <limit effort="0.0" lower="0.0" upper="0.08" velocity="0.0"/>
  </joint>
  <joint name="brake_joint" type="prismatic">
    <parent link="chassis"/>
    <child link="brake_pedal"/>
    <origin rpy="0  0  0" xyz="0.64     0.27     0.57999"/>
    <axis xyz="0.85749  0      -0.51449"/>
    <limit effort="0.0" lower="0.0" upper="0.08" velocity="0.0"/>
  </joint>
  <!--
  <joint name="steering_joint" type="revolute">
    <parent link="chassis"/>
    <child link="steering_wheel"/>
    <origin rpy="0   -0.87  0" xyz="0.42  0.46  1.2"/>
    <axis xyz="0  0  1"/>
    <limit effort="0.0" lower="-3.14" upper="3.14" velocity="0.0"/>
  </joint>
  <joint name="hand_brake_joint" type="revolute">
    <parent link="chassis"/>
    <child link="hand_brake"/>
    <origin rpy="0  0  0" xyz="0.53   0.205  1.05"/>
    <axis xyz="0 -1  0"/>
    <limit effort="0.0" lower="0.0" upper="0.6" velocity="0.0"/>
  </joint>-->
  <joint name="FNR_switch_joint" type="revolute">
    <parent link="chassis"/>
    <child link="FNR_switch"/>
    <origin rpy="0    0.25  0" xyz="0.54     0.1      1.14999"/>
    <axis xyz="0 -1  0"/>
    <limit effort="0.0" lower="-0.3" upper="0.3" velocity="0.0"/>
  </joint>
  <link name="chassis">
    <inertial>
      <mass value="720.0"/>
      <origin rpy="0  0  0" xyz="0.1  0   0.4"/>
      <inertia ixx="140" ixy="0.0" ixz="0.0" iyy="550" iyz="0.0" izz="550"/>
    </inertial>
    <collision name="chassis_bottom">
      <origin rpy="0  0  0" xyz="0.2    0     0.335"/>
      <geometry>
        <box size="1.34 1.65746 0.06"/>
      </geometry>
    </collision>
    <visual name="visual">
      <origin rpy="0  0  0" xyz="0.2    0     0.335"/>
      <geometry>
        <box size="1.34 1.65746 0.06"/>
      </geometry>
    </visual>
  </link>
  <link name="front_left_wheel">
    <inertial>
      <mass value="12"/>
      <origin rpy="0  0  0" xyz="0  0  0"/>
      <inertia ixx="0.5" ixy="0.0" ixz="0.0" iyy="0.5" iyz="0.0" izz="1.0"/>
    </inertial>
    <collision name="collision">
      <origin rpy="0  0  0" xyz="0  0  0"/>
      <geometry>
        <cylinder length="0.2794" radius="0.3175"/>
      </geometry>
    </collision>
    <visual name="tire_visual">
      <origin rpy="0  0  0" xyz="0  0  0"/>
      <geometry>
        <cylinder length="0.2794" radius="0.3175"/>
      </geometry>
    </visual>
  </link>
  <link name="front_right_wheel">
    <inertial>
      <mass value="12"/>
      <origin rpy="0  0  0" xyz="0  0  0"/>
      <inertia ixx="0.5" ixy="0.0" ixz="0.0" iyy="0.5" iyz="0.0" izz="1.0"/>
    </inertial>
    <collision name="collision">
      <origin rpy="0  0  0" xyz="0  0  0"/>
      <geometry>
        <cylinder length="0.2794" radius="0.3175"/>
      </geometry>
    </collision>
    <visual name="visual">
      <origin rpy="0  0  0" xyz="0  0  0"/>
      <geometry>
        <cylinder length="0.2794" radius="0.3175"/>
      </geometry>
    </visual>
  </link>
  <link name="rear_left_wheel">
    <inertial>
      <mass value="12"/>
      <origin rpy="0  0  0" xyz="0  0  0"/>
      <inertia ixx="0.5" ixy="0.0" ixz="0.0" iyy="0.5" iyz="0.0" izz="1.0"/>
    </inertial>
    <collision name="collision">
      <origin rpy="0  0  0" xyz="0  0  0"/>
      <geometry>
        <cylinder length="0.2794" radius="0.3175"/>
      </geometry>
    </collision>
    <visual name="visual">
      <origin rpy="0  0  0" xyz="0  0  0"/>
      <geometry>
        <cylinder length="0.2794" radius="0.3175"/>
      </geometry>
    </visual>
  </link>
  <link name="rear_right_wheel">
    <inertial>
      <mass value="12"/>
      <origin rpy="0  0  0" xyz="0  0  0"/>
      <inertia ixx="0.5" ixy="0.0" ixz="0.0" iyy="0.5" iyz="0.0" izz="1.0"/>
    </inertial>
    <collision name="collision">
      <origin rpy="0  0  0" xyz="0  0  0"/>
      <geometry>
        <cylinder length="0.2794" radius="0.3175"/>
      </geometry>
    </collision>
    <visual name="visual">
      <origin rpy="0  0  0" xyz="0  0  0"/>
      <geometry>
        <cylinder length="0.2794" radius="0.3175"/>
      </geometry>
    </visual>
  </link>
  <link name="gas_pedal">
    <inertial>
      <mass value="0.1"/>
      <origin rpy="0  0  0" xyz="0  0  0"/>
      <inertia ixx="0.01" ixy="0" ixz="0" iyy="0.01" iyz="0" izz="0.01"/>
    </inertial>
    <collision name="gas_pedal_collision">
      <origin rpy="3.14159  1.12559  3.14159" xyz="-0.0385  0     -0.086"/>
      <geometry>
        <box size="0.1069000 0.0770000 0.010000"/>
      </geometry>
    </collision>
    <visual name="visual">
      <origin rpy="3.14159  1.12559  3.14159" xyz="-0.0385  0     -0.086"/>
      <geometry>
        <box size="0.1069000 0.0770000 0.010000"/>
      </geometry>
    </visual>
  </link>
  <link name="brake_pedal">
    <inertial>
      <mass value="0.1"/>
      <origin rpy="0  0  0" xyz="0  0  0"/>
      <inertia ixx="0.01" ixy="0" ixz="0" iyy="0.01" iyz="0" izz="0.01"/>
    </inertial>
    <collision name="brake_pedal_collision">
      <origin rpy="3.14159  1.14259  3.14159" xyz="-0.04   0    -0.086"/>
      <geometry>
        <box size="0.063 0.08 0.01"/>
      </geometry>
    </collision>
    <visual name="visual">
      <origin rpy="3.14159  1.14259  3.14159" xyz="-0.04   0    -0.086"/>
      <geometry>
        <box size="0.063 0.08 0.01"/>
      </geometry>
    </visual>
  </link>
  <link name="front_right_wheel_steering_block">
    <inertial>
      <mass value="1"/>
      <origin rpy="0  0  0" xyz="0  0  0"/>
      <inertia ixx="1.0" ixy="0.0" ixz="0.0" iyy="1.0" iyz="0.0" izz="1.0"/>
    </inertial>
    <collision name="collision">
      <origin rpy="0  0  0" xyz="0  0  0"/>
      <geometry>
        <cylinder length="0.01" radius="0.05"/>
      </geometry>
    </collision>
  </link>
  <link name="front_left_wheel_steering_block">
    <inertial>
      <mass value="1"/>
      <origin rpy="0  0  0" xyz="0  0  0"/>
      <inertia ixx="1.0" ixy="0.0" ixz="0.0" iyy="1.0" iyz="0.0" izz="1.0"/>
    </inertial>
    <collision name="collision">
      <origin rpy="0  0  0" xyz="0  0  0"/>
      <geometry>
        <cylinder length="0.01" radius="0.05"/>
      </geometry>
    </collision>
  </link>
  <!--<link name="steering_wheel">
    <inertial>
      <mass value="1.0"/>
      <origin rpy="0  0  0" xyz="-0.002  0     0"/>
      <inertia ixx="0.012" ixy="0" ixz="0" iyy="0.012" iyz="0" izz="0.024"/>
    </inertial>
    <collision name="collision">
      <origin rpy="-0.6108   0      -1.57079" xyz="-0.03     0      -0.12082"/>
      <geometry>
        <mesh filename="package://meshes/polaris.dae" scale="1.0 1.0 1.0"/>
      </geometry>
    </collision>
    <visual name="visual">
      <origin rpy="-0.6108   0      -1.57079" xyz="-0.03     0      -0.12082"/>
      <geometry>
        <mesh filename="package://meshes/polaris.dae" scale="1.0 1.0 1.0"/>
      </geometry>
    </visual>
  </link>-->
  <!--
  <link name="hand_brake">
    <inertial>
      <mass value="0.5"/>
      <origin rpy="0  0  0" xyz="0  0  0"/>
      <inertia ixx="0.1" ixy="0" ixz="0" iyy="0.1" iyz="0" izz="0.05"/>
    </inertial>
    <collision name="hand_brake_collision">
      <origin rpy="-0.2      0      -1.57079" xyz="0    0    0.05"/>
      <geometry>
        <mesh filename="package://meshes/polaris.dae" scale="1.0 1.0 1.0"/>
      </geometry>
    </collision>
    <visual name="hand_brake_visual">
      <origin rpy="-0.2      0      -1.57079" xyz="0    0    0.05"/>
      <geometry>
        <mesh filename="package://meshes/polaris.dae" scale="1.0 1.0 1.0"/>
    </visual>
  </link>-->
  <link name="FNR_switch">
    <inertial>
      <mass value="0.1"/>
      <origin rpy="0  0  0" xyz="0  0  0"/>
      <inertia ixx="0.1" ixy="0" ixz="0" iyy="0.00006" iyz="0" izz="0.1"/>
    </inertial>
    <collision name="FNR_switch">
      <origin rpy="0  0  0" xyz="0  0  0"/>
      <geometry>
        <box size="0.02 0.04 0.08"/>
      </geometry>
    </collision>
    <visual name="FNR_switch_F">
      <origin rpy="0  0  0" xyz="0  0  0"/>
      <geometry>
        <box size="0.02 0.04 0.08"/>
      </geometry>
    </visual>
  </link>
</robot>
